Workbook

Sheet Test_Plan
A1: Test plan – what to measure
A2: Priority A = key figures of the documentation and input for the software · B = clearly strengthens the documentation · C = nice to have
A4: ID | B4: Prio | C4: Test | D4: Goal / documentation section | E4: Setup & equipment | F4: Procedure | G4: Result → sheet | H4: Status
A5: T01 | B5: A | C5: Masses of all components | D5: 2.0 Key figures, basis for CoG, traction, τ | E5: Precision scale (0.1 g) | F5: Weigh the robot ready to drive (with battery), then disassemble and weigh every component listed in Mass_CoG individually. The sum must match the total mass within ±2 %. | G5: Mass_CoG | H5: done
A6: T02 | B6: A | C6: Axle loads & centre of gravity (scale/tilt method) | D6: 2.1.2 CoG x/y/z, axle load distribution | E6: 2 identical kitchen scales (or 1 scale + block of equal height), wooden blocks/spacers of known height | F6: Front axle on scale A, rear axle on a support of equal height → m_front. Then the other way round → m_rear. Same for left/right. Tilt test: raise the rear axle by 20–30 mm and measure the front axle load again → z_CoG. Repeat every measurement 3×. | G6: Mass_CoG | H6: done
A7: T03 | B7: A | C7: Fusion CoG with effective densities | D7: 2.1.7 Validation of the digital twin | E7: Fusion: physical properties | F7: Mass from T01 divided by CAD volume gives the effective density (listed in Mass_CoG). Create a separate material with this density for each part; Fusion then shows the CoG. Important: FDM parts with 12 % infill are much lighter than solid material, so do not use the standard PLA density. | G7: Mass_CoG | H7: done (Fusion)
A8: T04 | B8: A | C8: Encoder calibration / effective wheel diameter | D8: 2.3.6 and software (m/s calibration) | E8: Tape measure, tape markings, encoder log | F8: Drive 2.00 m straight slowly, log encoder counts, 5× per direction. This gives counts per metre and the effective wheel diameter under load (the silicone deforms). | G8: Drivetrain | H8: done
A9: T05 | B9: A | C9: Static steering angles target/actual incl. hysteresis | D9: 2.2.4 Measurement series (successor of the old table) | E9: Robot on the stand, protractor or photo from directly above + evaluation (e.g. Kinovea/GIMP) | F9: Move to 9 steering commands from full left to full right, once approaching from the left (forward) and once from the right (return). Measure the left AND right wheel angle each time; this gives the Ackermann check on the real robot. | G9: Steering_Target_Actual | H9: done
A10: T06 | B10: A | C10: Turning radius per steering command + turning circle | D10: 2.2.5, 2.0 turning circle, steering LUT | E10: Field, log IMU yaw rate + encoder speed, tape measure as a check | F10: Drive 2 full circles with a constant steering command and slowly (approx. 0.2 m/s). R = v / ψ̇. For 1–2 commands also measure the circle diameter directly (marker under the rear-axle centre or video from above). Drive both directions. Full lock gives the turning circle. | G10: Radius_v | H10: done
A11: T07 | B11: A | C11: Step response & top speed | D11: 2.3.3 τ, v_max (replaces the old theory) | E11: Encoder log at a high rate (≥ 50 Hz), straight track ≥ 2 m | F11: From standstill, step to 100 % PWM (and to competition PWM). Measure once with a full battery (16.8 V) and once at nominal voltage (~14.8 V). Copy the columns t and v as CSV into the sheet Step_Log. | G11: Step_Log / Drivetrain | H11: done
A12: T08 | B12: A | C12: Friction coefficient of the silicone tyres (longitudinal/lateral, clean/dusty) | D12: 2.3.6 Tyres, traction and cornering limit | E12: Board with a piece of field mat, protractor/phone inclination app | F12: Place the robot on the mat and tilt the board slowly until it slides. μ = tan α. Lateral: robot placed sideways. Longitudinal: wheels blocked (the motor holds them through the gearbox). 5× clean and 5× after 3 runs without cleaning each. If still available: LEGO Spike tyres for comparison. | G12: Grip_Tipping | H12: done
A13: T09 | B13: B | C13: Radius vs. speed (understeer) | D13: 2.2.5 Understeer gradient, steering LUT | E13: as T06 | F13: Repeat T06 for 3–4 steering commands at 0.2 / 0.4 / 0.6 / 0.8 m/s. This shows how strongly the robot understeers with lateral acceleration. | G13: Radius_v | H13: done
A14: T10 | B14: B | C14: Stall torque & stall current | D14: 2.3.3 Motor characteristic | E14: Lever arm (e.g. 50 mm rod on the shaft), kitchen scale, lab power supply with current display | F14: Fix the robot at 12 V, the lever presses on the scale, apply full voltage briefly (< 2 s). M = F·r. Read the current. Do not stall any longer, otherwise the motor and the brass bevel gears suffer. | G14: Drivetrain | H14: not measurable – traction limit (journal 3.1.7.2)
A15: T11 | B15: B | C15: Braking distance & coast-down test | D15: 2.3.3 Braking behaviour, rolling resistance | E15: Encoder log | F15: Drive at competition speed, then (a) brake actively and (b) set PWM to 0 and let it coast. Read distance and time from the log. | G15: Drivetrain | H15: done
... A23: T18 | B23: C | C23: Maintainability: assembly times | D23: 2.1.3 Maintainability | E23: Stopwatch | F23: Time battery change, motor swap, servo swap and full assembly (estimated 40–60 min) once for real. | G23: (documentation table) | H23: done
A25: Resulting calculations
A26: ID | B26: Prio | C26: Calculation | D26: Purpose | E26: Input | F26: Formula / method | G26: Sheet | H26: Status
A27: R01 | B27: A | C27: Centre of gravity x/y/z (CAD and real) | D27: CoG comparison old/new, tipping limit, traction | E27: T01, T02 | F27: x = Σ(m·x)/Σm; scales: x = L·m_f/m, z = r + L·Δm_f/(m·tanθ) | G27: Mass_CoG | H27: open
A28: R02 | B28: A | C28: Ackermann analysis over the full steering range | D28: 2.2.3: substantiate or refine “100 % Ackermann” | E28: CAD points (done), T05 | F28: Linkage vs. ideal: cot δo − cot δi = k/L | G28: Ackermann_CAD | H28: open
A29: R03 | B29: A | C29: Minimum turning radius / turning circle | D29: 2.0, parking challenge | E29: R02, T06 | F29: R = L/tan δ + k/2 or measured v/ψ̇ | G29: Ackermann_CAD / Radius_v | H29: open
A30: R04 | B30: A | C30: Theoretical vs. measured top speed | D30: 2.3.3 (replaces the old v_max calculation) | E30: Data sheet, T04, T07 | F30: v = n·π·d/60, n ~ U (no load, linear) | G30: Drivetrain | H30: open
A31: R05 | B31: A | C31: Time constant τ from measurement | D31: 2.3.3 (replaces the theoretical τ) | E31: T07 | F31: t at 63.2 % of the final speed | G31: Step_Log | H31: open
A32: R06 | B32: A | C32: Traction limit of rear-wheel drive vs. motor limit | D32: 2.3.3: what limits acceleration? | E32: R01, T08, T10 | F32: a_grip = μ·g·(l_f/L)/(1 − μ·h/L); a_motor = M·i/(r·m) | G32: Drivetrain | H32: open
A33: R07 | B33: A | C33: Wheel slip caused by the rigid rear axle | D33: 2.3.5: reason for understeer, trade-off “no differential” | E33: Track width, R | F33: Slip per rear wheel ≈ ± T/(2R) | G33: Grip_Tipping | H33: open
A34: R08 | B34: B | C34: Cornering speed limit | D34: 2.3.6, software target speed | E34: T08 | F34: v_max(R) = √(μ_lat·g·R) | G34: Grip_Tipping | H34: open
A35: R09 | B35: B | C35: Tipping vs. sliding limit | D35: 2.3.6 Stability (successor of “CoG 10 mm lower”) | E35: R01, T08 | F35: a_tip = g·(T/2)/h; never tips if μ < T/(2h) | G35: Grip_Tipping | H35: open
A36: R10 | B36: B | C36: Understeer gradient | D36: 2.2.5 | E36: T09 | F36: δ_stat − δ_eff = K·a_y → slope K in °/(m/s²) | G36: Radius_v | H36: open
A37: R11 | B37: B | C37: Encoder resolution in mm/count | D37: 2.3, software | E37: T04 | F37: s / N | G37: Drivetrain | H37: open
... A39: R13 | B39: B | C39: Comparison table old ↔ new | D39: Start of chapter | E39: everything | F39: Mass, dimensions, wheelbase, steering angle, turning circle, play, v_max, τ, CoG | G39: (documentation) | H39: open
A41: To-do: send data and material
A42: ☐ | B42: All measurement data as CSV or this Excel filled in (encoder, IMU, PI controller target/actual, motor current if measurable)
A43: ☐ | B43: rosbag extracts of tests T04, T06, T07, T09, T11 as CSV (ros2 bag → CSV, e.g. via Foxglove export)
A44: ☐ | B44: Ask for silicone material data (manufacturer, Shore hardness, mixing ratio, pot life) and release agent
A45: ☐ | B45: Photos: tyre casting (mould, funnel, finished tyre), broken C-profiles / worn FDM ball heads, old robot from the same perspective
A46: ☐ | B46: Exploded view from Fusion (title image of the chapter) and screenshots of the steering straight ahead / full lock from above
A47: ☐ | B47: Data sheet or shop data for motor 25GA370 (1000 RPM @ 12 V): confirm no-load current, stall current, rated torque, gearbox 15.4:1, encoder pulses per revolution
A48: ☐ | B48: Fusion: CoG value after T03 (screenshot “Properties”)

Sheet Quick_Guide
A1: Quick guide – how to run the tests
A2: Practical steps only: prepare the robot, place it, let it drive, read the values. The last column says where the values go.
A4: ID | B4: Test | C4: Prepare the robot | D4: Place / position | E4: Drive / procedure | F4: Measure & record | G4: How often | H4: Enter in
A5: T01 | B5: Weighing | C5: Full battery in, body on, as in competition. Do not let cables hang off the table. | D5: Place it in the middle of the precision scale; tare the scale to 0 beforehand. | E5: – | F5: First weigh the complete robot, then remove the body and weigh again. Then unscrew part by part and weigh each one individually. Collect the screws per assembly and weigh them together. Weigh cables/Velcro together at the end. | G5: Total 3×, single parts 1× | H5: Mass_CoG, column K
A6: T02 | B6: Axle loads & centre of gravity | C6: Ready to drive with battery and body. Steering straight, motor off (the gearbox holds the rear wheels). | D6: Two scales of equal height next to each other. If you only have one, use a book/block of exactly the same height instead of the second (check with a caliper). (1) Front wheels on scale A, rear wheels on scale B. (2) Turn the robot sideways: left wheels on A, right wheels on B. (3) Tilt: front wheels on the scale, a block of 20–30 mm height under both rear wheels. | E6: – | F6: (1) Load front and rear. (2) Load left and right. (3) Front load in the tilted state plus the exact block height. Check beforehand that front + rear roughly equals the total weight. | G6: Each position 3×, re-place every time | H6: Mass_CoG, scale block
A7: T03 | B7: Fusion centre of gravity | C7: No robot needed; finish T01 first. | D7: Fusion: open Napoleon. | E7: Create a separate material for each part (copy material) and enter the density from column O of Mass_CoG. Then open the properties of the top-level component. | F7: Write down mass and CoG x/y/z (in Fusion coordinates) and take a screenshot. Once with, once without the body component. | G7: 1× with, 1× without body | H7: Send screenshot
A8: T04 | B8: Encoder distance | C8: Full battery, steering straight, logging on: encoder counts with time. | D8: Straight track on the mat. Start line with tape, finish line 2.00 m further (with tape measure). Place the robot so that the rear axle is exactly above the start line. | E8: Drive straight slowly (approx. 0.2–0.3 m/s) and stop just after the finish line. | F8: Measure with the tape how far the rear axle actually travelled (start to stop position). Record the encoder counts for exactly this run. | G8: 5× forward, 5× in the opposite direction | H8: Drivetrain, encoder table
A9: T05 | B9: Steering angle at standstill | C9: Robot on the stand, front wheels free in the air. Stick a straight stick or ruler to the outside of each front wheel (as a pointer, not on the tread). | D9: Phone exactly vertical above the front axle (tripod or stack of books), always the same position. A straight chassis edge must be in the picture; it is the zero line. | E9: Forward: send steering commands step by step from full left to full right (9 steps), one photo per step. Return: the same from full right back to full left. | F9: Read the angle of the left and right wheel against the chassis edge from each photo (e.g. with GIMP, Kinovea or a protractor app). Positive = to the left. Note the steering command. | G9: Each step forward + return | H9: Steering_Target_Actual
A10: T06 | B10: Driving circles | C10: Full battery, body on. Logging: IMU yaw rate and encoder speed. Control off, fixed steering command only. | D10: Free spot in the middle of the mat. Mark the position of the rear-axle centre at the start with a piece of tape. | E10: Set a fixed steering command and drive slowly (0.2 m/s) at constant speed, two full circles. If the circle is larger than the mat: drive as far as there is room, at least half a circle. Once to the left, once to the right. | F10: Stop after exactly half a lap and mark the rear-axle centre again. The distance between the two marks is the circle diameter. Send the log (v and yaw rate). Full lock = turning circle. | G10: All 9 steering steps, left + right each | H10: Radius_v
A11: T07 | B11: Full throttle from standstill | C11: Program: from standstill immediately 100 % PWM for approx. 1.5 s, then brake. Logging at at least 50 Hz: time and speed (current if measurable). | D11: Longest free straight on the mat, steering straight. Someone to catch the robot at the end, or a soft obstacle. | E11: Start, let it drive, brake. Once with a freshly charged battery (approx. 16.8 V), once at approx. 14.8 V. If possible, also with the competition PWM. | F11: Copy the log as CSV (columns t and v) into Step_Log. Note the battery voltage before the start. | G11: 3× per battery state | H11: Step_Log
A12: T08 | B12: Sliding board | C12: Firmly cover a board (min. 40 cm) with a piece of field mat. Place a phone with an inclination app on the board. Robot ready to drive, motor off. | D12: Lateral: place the robot sideways on the board (wheels across the slope). Longitudinal: robot pointing downhill; fix the front wheels to the C-profile with tape beforehand (not on the tread). The gearbox holds the rear wheels. | E12: Raise the board slowly and evenly until the robot starts to slide. If it tips instead: stop immediately and note it! | F12: Read the angle at the moment it slides. Once with freshly cleaned tyres, once after 3 runs without cleaning. If still available: LEGO Spike tyres for comparison. | G12: 5× per variant | H12: Grip_Tipping
A13: T09 | B13: Faster circles | C13: As T06. | D13: As T06; leave enough room all around. | E13: 3–4 fixed steering steps, each at 0.2 / 0.4 / 0.6 / 0.8 m/s. As soon as it slides or reaches the wall: stop and note at which speed. | F13: Send the logs (v, yaw rate). At high speeds the log is enough; no tape measure needed. | G13: 1–2× per combination | H13: Radius_v
A14: T10 | B14: Stalling with a lever | C14: Clamp or tie a ruler/rod firmly to a rear wheel (pointing radially outwards). Motor directly on the lab power supply: 12 V, current limit e.g. 3 A. | D14: Hold the robot on its back or side with a clamp. The end of the lever rests on a kitchen scale. Measure the distance from the axle centre to the contact point on the scale. | E14: Apply voltage briefly (under 2 s!) so that the lever presses on the scale, then switch off immediately. 30 s pause between measurements. | F14: Record the scale reading in grams, the current on the power supply and the lever distance in mm. | G14: 3× | H14: Drivetrain (B16/B17)
A15: T11 | B15: Braking & coasting | C15: Logging: time, speed, distance travelled. | D15: Long straight. Mark the braking point with tape or set it in the code to a fixed distance. | E15: Accelerate to competition speed. At the braking point (a) give the brake command, (b) only set PWM to 0 and let it coast. | F15: Measure the distance from the braking point to standstill (rear axle) with the tape, plus the speed at the start of braking from the log. | G15: 3× each | H15: Drivetrain, braking block
... A23: T19 | B23: Body | C23: Body with LEDs and built-in camera, robot ready to drive. | D23: Robot on the table. | E23: Remove and refit the body 10× and check each time whether the LEDs and camera work immediately (pogo pins). Then drive 3 normal runs and watch whether the contact breaks or the body wobbles. | F23: Mass of the body with LEDs (camera separately), the time to fit it and how often the contact was not there immediately. Photos with and without body from the same perspective. | G23: Fit 10×, 3 runs | H23: Mass_CoG + photos

Sheet Mass_CoG
A1: Masses & centre of gravity (CoG)
A2: CAD centroids from Chassis_Vertikal.step (volume centroid per part) · masses measured with a precision scale
A4: Reference points (CAD coordinates in mm)
A5: x rear axle (CAD) | B5: 68.6 | C5: Axis of the D-shaft
A6: y vehicle centre (CAD) | B6: -15.3 | C6: Centre between the rear wheels
A7: z ground (CAD) | B7: -4.4 | C7: Bottom edge of the rear wheels
A8: Wheelbase L | B8: 102 | C8: Kingpin axis to rear axle
A9: Track width rear T | B9: 96.2 | C9: Wheel centre to wheel centre
A10: Wheel radius r | B10: 16 | C10: Ø 32 mm
A13: Component | B13: Group | C13: Material / type | D13: CAD volume [cm³] | E13: x CAD | F13: y CAD | G13: z CAD | H13: x veh [mm] (forward +) | I13: y veh [mm] (left +) | J13: z veh [mm] (up +) | K13: Measured mass [g] | L13: m·x | M13: m·y | N13: m·z | O13: eff. density [g/cm³] → Fusion
A14: Example: battery 4S 450 mAh | B14: Energy | C14: Purchased part | D14: 28.07 | E14: 62 | F14: -40.3 | G14: 37.5 | H14: 6.6 | I14: 25 | J14: 41.9 | K14: 58.3
A15: LiDAR Slamtec RPLiDAR S3 | B15: Sensors | C15: Purchased part | D15: 25.52 | E15: -42.34 | F15: -15.3 | G15: 32.58 | H15: =$B$5-E15 -> 110.94 | I15: =-(F15-$B$6) -> 0 | J15: =G15-$B$7 -> 36.98 | L15: =IF(K15="","",K15*H15) -> 11648.7 | M15: =IF(K15="","",K15*I15) -> 0 | N15: =IF(K15="","",K15*J15) -> 3882.9 | O15: =IF(K15="","",K15/D15) -> 4.1144201
A16: Steering servo Waveshare SC09 | B16: Steering | C16: Purchased part | D16: 2.15 | E16: -49.89 | F16: -16.89 | G16: 11.05 | H16: =$B$5-E16 -> 118.49 | I16: =-(F16-$B$6) -> 1.59 | J16: =G16-$B$7 -> 15.45 | L16: =IF(K16="","",K16*H16) -> 2488.29 | M16: =IF(K16="","",K16*I16) -> 33.39 | N16: =IF(K16="","",K16*J16) -> 324.45 | O16: =IF(K16="","",K16/D16) -> 9.7674419
A17: Front / steering carrier (body) | B17: Structure | C17: FDM PLA Matte | D17: 12.14 | E17: -52.94 | F17: -14.46 | G17: 10.69 | H17: =$B$5-E17 -> 121.54 | I17: =-(F17-$B$6) -> -0.84 | J17: =G17-$B$7 -> 15.09 | L17: =IF(K17="","",K17*H17) -> 1020.936 | M17: =IF(K17="","",K17*I17) -> -7.056 | N17: =IF(K17="","",K17*J17) -> 126.756 | O17: =IF(K17="","",K17/D17) -> 0.69192751
A18: C-profile left incl. bearing | B18: Steering | C18: SLA ABS-Like Pro 2 | D18: 1.42 | E18: -31.33 | F18: -50.16 | G18: 10.95 | H18: =$B$5-E18 -> 99.93 | I18: =-(F18-$B$6) -> 34.86 | J18: =G18-$B$7 -> 15.35 | L18: =IF(K18="","",K18*H18) -> 159.888 | M18: =IF(K18="","",K18*I18) -> 55.776 | N18: =IF(K18="","",K18*J18) -> 24.56 | O18: =IF(K18="","",K18/D18) -> 1.1267606
A19: C-profile right incl. bearing | B19: Steering | C19: SLA ABS-Like Pro 2 | D19: 1.42 | E19: -31.32 | F19: 19.55 | G19: 10.95 | H19: =$B$5-E19 -> 99.92 | I19: =-(F19-$B$6) -> -34.85 | J19: =G19-$B$7 -> 15.35 | L19: =IF(K19="","",K19*H19) -> 159.872 | M19: =IF(K19="","",K19*I19) -> -55.76 | N19: =IF(K19="","",K19*J19) -> 24.56 | O19: =IF(K19="","",K19/D19) -> 1.1267606
A20: Connector / tie rod | B20: Steering | C20: Metal/SLA | D20: 0.52 | E20: -15.7 | F20: -15.3 | G20: 14.59 | H20: =$B$5-E20 -> 84.3 | I20: =-(F20-$B$6) -> 0 | J20: =G20-$B$7 -> 18.99 | L20: =IF(K20="","",K20*H20) -> 345.63 | M20: =IF(K20="","",K20*I20) -> 0 | N20: =IF(K20="","",K20*J20) -> 77.859 | O20: =IF(K20="","",K20/D20) -> 7.8846154
A21: Servo horn | B21: Steering | C21: SLA ABS-Like Pro 2 | D21: 0.27 | E21: -35.47 | F21: -13.75 | G21: 5.54 | H21: =$B$5-E21 -> 104.07 | I21: =-(F21-$B$6) -> -1.55 | J21: =G21-$B$7 -> 9.94 | L21: =IF(K21="","",K21*H21) -> 31.221 | M21: =IF(K21="","",K21*I21) -> -0.465 | N21: =IF(K21="","",K21*J21) -> 2.982 | O21: =IF(K21="","",K21/D21) -> 1.1111111
A22: Tie-rod end 1 | B22: Steering | C22: Purchased part | D22: 0.24 | E22: -28.02 | F22: -9.06 | G22: 1.42 | H22: =$B$5-E22 -> 96.62 | I22: =-(F22-$B$6) -> -6.24 | J22: =G22-$B$7 -> 5.82 | L22: =IF(K22="","",K22*H22) -> 183.578 | M22: =IF(K22="","",K22*I22) -> -11.856 | N22: =IF(K22="","",K22*J22) -> 11.058 | O22: =IF(K22="","",K22/D22) -> 7.9166667
A23: Tie-rod end 2 | B23: Steering | C23: Purchased part | D23: 0.24 | E23: -20.55 | F23: 5.84 | G23: 5.44 | H23: =$B$5-E23 -> 89.15 | I23: =-(F23-$B$6) -> -21.14 | J23: =G23-$B$7 -> 9.84 | L23: =IF(K23="","",K23*H23) -> 169.385 | M23: =IF(K23="","",K23*I23) -> -40.166 | N23: =IF(K23="","",K23*J23) -> 18.696 | O23: =IF(K23="","",K23/D23) -> 7.9166667
A24: Connector helper | B24: Steering | C24: SLA | D24: 0.08 | E24: -24.28 | F24: -1.61 | G24: 3.43 | H24: =$B$5-E24 -> 92.88 | I24: =-(F24-$B$6) -> -13.69 | J24: =G24-$B$7 -> 7.83 | L24: =IF(K24="","",K24*H24) -> 9.288 | M24: =IF(K24="","",K24*I24) -> -1.369 | N24: =IF(K24="","",K24*J24) -> 0.783 | O24: =IF(K24="","",K24/D24) -> 1.25
A25: Pogo-pin plate | B25: Structure | C25: Purchased part/FDM | D25: 0.49 | E25: -74.25 | F25: -15.3 | G25: 12.9 | H25: =$B$5-E25 -> 142.85 | I25: =-(F25-$B$6) -> 0 | J25: =G25-$B$7 -> 17.3 | L25: =IF(K25="","",K25*H25) -> 214.275 | M25: =IF(K25="","",K25*I25) -> 0 | N25: =IF(K25="","",K25*J25) -> 25.95 | O25: =IF(K25="","",K25/D25) -> 3.0612245
A26: Front wheel left (rim+silicone) | B26: Wheels | C26: PA6-CF + silicone | D26: 8.91 | E26: -33.4 | F26: -63.89 | G26: 10.78 | H26: =$B$5-E26 -> 102 | I26: =-(F26-$B$6) -> 48.59 | J26: =G26-$B$7 -> 15.18 | L26: =IF(K26="","",K26*H26) -> 775.2 | M26: =IF(K26="","",K26*I26) -> 369.284 | N26: =IF(K26="","",K26*J26) -> 115.368 | O26: =IF(K26="","",K26/D26) -> 0.85297419
... A41: Screws chassis/motor | B41: Small parts | C41: Steel | D41: 0.22 | E41: 52.6 | F41: -38.11 | G41: 11.2 | H41: =$B$5-E41 -> 16 | I41: =-(F41-$B$6) -> 22.81 | J41: =G41-$B$7 -> 15.6 | L41: =IF(K41="","",K41*H41) -> 27.2 | M41: =IF(K41="","",K41*I41) -> 38.777 | N41: =IF(K41="","",K41*J41) -> 26.52 | O41: =IF(K41="","",K41/D41) -> 7.7272727
A42: Camera Picam360 (in the body) | B42: Body | C42: Purchased part | D42: 9.99 | E42: -42.2 | F42: -15.3 | G42: 68.2 | H42: =$B$5-E42 -> 110.8 | I42: =-(F42-$B$6) -> 0 | J42: =G42-$B$7 -> 72.6 | K42: 23.05 | L42: =IF(K42="","",K42*H42) -> 3324 | M42: =IF(K42="","",K42*I42) -> 0 | N42: =IF(K42="","",K42*J42) -> 2178 | O42: =IF(K42="","",K42/D42) -> 3.003003
A43: Body VW T1 (shell, incl. LEDs/pogo counterpart) | B43: Body | C43: 3D print | D43: 116.35 | E43: 8.5 | F43: -15.3 | G43: 41.3 | H43: =$B$5-E43 -> 60.1 | I43: =-(F43-$B$6) -> 0 | J43: =G43-$B$7 -> 45.7 | L43: =IF(K43="","",K43*H43) -> 2283.8 | M43: =IF(K43="","",K43*I43) -> 0 | N43: =IF(K43="","",K43*J43) -> 1736.6 | O43: =IF(K43="","",K43/D43) -> 0.32660077
A44: Cables, Velcro, other (not in CAD) | B44: Other | E44: 30 | F44: -2 | G44: 45 | H44: =IF(E44="","",$B$5-E44) -> 38.6 | I44: =IF(F44="","",-(F44-$B$6)) -> -13.3 | J44: =IF(G44="","",G44-$B$7) -> 49.4 | L44: =IF(OR(K44="",H44=""),"",K44*H44) -> 617.6 | M44: =IF(OR(K44="",I44=""),"",K44*I44) -> -212.8 | N44: =IF(OR(K44="",J44=""),"",K44*J44) -> 790.4
A46: Result, CAD method (sum of single masses) | B46: without body | C46: with body (competition)
A47: Σ mass [g] | B47: =SUMIF(B15:B44,"<>Body",K15:K44) -> 505 | C47: =SUM(K15:K44) -> 573
A48: x_CoG ahead of rear axle [mm] | B48: =IF(B47=0,"",SUMIF(B15:B44,"<>Body",L15:L44)/B47) -> 58.023622 | C48: =IF(C47=0,"",SUM(L15:L44)/C47) -> 60.924483
A49: y_CoG left of centre [mm] | B49: =IF(B47=0,"",SUMIF(B15:B44,"<>Body",M15:M44)/B47) -> 3.7169327 | C49: =IF(C47=0,"",SUM(M15:M44)/C47) -> 3.2758307
A50: z_CoG above ground [mm] | B50: =IF(B47=0,"",SUMIF(B15:B44,"<>Body",N15:N44)/B47) -> 26.5148 | C50: =IF(C47=0,"",SUM(N15:N44)/C47) -> 30.199955
A51: Front axle load [%] | B51: =IF(B48="","",B48/$B$8) -> 0.56885904 | C51: =IF(C48="","",C48/$B$8) -> 0.59729886
A52: Share weighed (components with mass) | C52: =COUNT(K15:K43)/29 -> 1
A54: Scale & tilt method (real validation)
A55: Total mass ready to drive [g] | B55: 586
A56: Front axle load [g] | B56: 322
A57: Rear axle load [g] | B57: 257
A58: Left side load [g] | B58: 284
A59: Right side load [g] | B59: 295
...

Sheet Steering_Target_Actual
A1: Steering target/actual – static measurement series (successor of table 1 / graph 1)
A2: Robot on the stand, wheels free. Angle positive = to the left. Forward = position approached from the left, Return = approached from the right.
A4: Parameter
A5: Wheelbase L [mm] | B5: =Mass_CoG!B8 -> 102
A6: Kingpin distance k [mm] | B6: 59.3 | C6: from STEP (rivet pivots)
A7: Servo centre / stops [°] | B7: 15.69 / +83.62 / −82.16
A9: Pos | B9: Steering command (software unit) | C9: Target steering angle δ_target [°] (bicycle) | D9: Left wheel forward [°] | E9: Left wheel return [°] | F9: Right wheel forward [°] | G9: Right wheel return [°] | H9: Left wheel mean [°] | I9: Right wheel mean [°] | J9: δ_actual bicycle [°] | K9: Deviation δ_actual − δ_target [°] | L9: Hysteresis left [°] | M9: Hysteresis right [°] | N9: δ_outer ideal [°] | O9: Ackermann error [°]
A10: Ex. | B10: 50 | C10: 20 | D10: 20.4 | E10: 19.8 | F10: 18.1 | G10: 17.6
A11: Pos1 | B11: -100 | C11: -45 | D11: -30 | F11: -47 | H11: =IF(COUNT(D11:E11)=0,"",AVERAGE(D11:E11)) -> -30 | I11: =IF(COUNT(F11:G11)=0,"",AVERAGE(F11:G11)) -> -47 | J11: =IF(OR(H11="",I11=""),"",IF(ABS(H11+I11)<0.05,0,DEGREES(ATAN(2/(1/TAN(RADIANS(H11))+1/TAN(RADIANS(I11))))))) -> -36.891574 | K11: =IF(OR(J11="",C11=""),"",J11-C11) -> 8.1084256 | L11: =IF(COUNT(D11:E11)<2,"",D11-E11) | M11: =IF(COUNT(F11:G11)<2,"",F11-G11) | N11: =IF(OR(H11="",I11=""),"",IF(ABS(H11)<0.05,0,SIGN(H11)*DEGREES(ATAN(1/(1/TAN(RADIANS(MAX(ABS(H11),ABS(I11))))+$B$6/$B$5))))) -> -33.446797 | O11: =IF(N11="","",SIGN(H11)*MIN(ABS(H11),ABS(I11))-N11) -> 3.4467966
A12: Pos2 | B12: -30 | C12: -13.5 | D12: -12.5 | F12: -12.5 | H12: =IF(COUNT(D12:E12)=0,"",AVERAGE(D12:E12)) -> -12.5 | I12: =IF(COUNT(F12:G12)=0,"",AVERAGE(F12:G12)) -> -12.5 | J12: =IF(OR(H12="",I12=""),"",IF(ABS(H12+I12)<0.05,0,DEGREES(ATAN(2/(1/TAN(RADIANS(H12))+1/TAN(RADIANS(I12))))))) -> -12.5 | K12: =IF(OR(J12="",C12=""),"",J12-C12) -> 1 | L12: =IF(COUNT(D12:E12)<2,"",D12-E12) | M12: =IF(COUNT(F12:G12)<2,"",F12-G12) | N12: =IF(OR(H12="",I12=""),"",IF(ABS(H12)<0.05,0,SIGN(H12)*DEGREES(ATAN(1/(1/TAN(RADIANS(MAX(ABS(H12),ABS(I12))))+$B$6/$B$5))))) -> -11.110546 | O12: =IF(N12="","",SIGN(H12)*MIN(ABS(H12),ABS(I12))-N12) -> -1.3894535
A13: Pos3 | B13: 30 | C13: 13.5 | D13: 13.5 | F13: 13.5 | H13: =IF(COUNT(D13:E13)=0,"",AVERAGE(D13:E13)) -> 13.5 | I13: =IF(COUNT(F13:G13)=0,"",AVERAGE(F13:G13)) -> 13.5 | J13: =IF(OR(H13="",I13=""),"",IF(ABS(H13+I13)<0.05,0,DEGREES(ATAN(2/(1/TAN(RADIANS(H13))+1/TAN(RADIANS(I13))))))) -> 13.5 | K13: =IF(OR(J13="",C13=""),"",J13-C13) -> 0 | L13: =IF(COUNT(D13:E13)<2,"",D13-E13) | M13: =IF(COUNT(F13:G13)<2,"",F13-G13) | N13: =IF(OR(H13="",I13=""),"",IF(ABS(H13)<0.05,0,SIGN(H13)*DEGREES(ATAN(1/(1/TAN(RADIANS(MAX(ABS(H13),ABS(I13))))+$B$6/$B$5))))) -> 11.896755 | O13: =IF(N13="","",SIGN(H13)*MIN(ABS(H13),ABS(I13))-N13) -> 1.6032448
A14: Pos4 | B14: 100 | C14: 45 | D14: 41 | F14: 33.5 | H14: =IF(COUNT(D14:E14)=0,"",AVERAGE(D14:E14)) -> 41 | I14: =IF(COUNT(F14:G14)=0,"",AVERAGE(F14:G14)) -> 33.5 | J14: =IF(OR(H14="",I14=""),"",IF(ABS(H14+I14)<0.05,0,DEGREES(ATAN(2/(1/TAN(RADIANS(H14))+1/TAN(RADIANS(I14))))))) -> 36.926314 | K14: =IF(OR(J14="",C14=""),"",J14-C14) -> -8.0736865 | L14: =IF(COUNT(D14:E14)<2,"",D14-E14) | M14: =IF(COUNT(F14:G14)<2,"",F14-G14) | N14: =IF(OR(H14="",I14=""),"",IF(ABS(H14)<0.05,0,SIGN(H14)*DEGREES(ATAN(1/(1/TAN(RADIANS(MAX(ABS(H14),ABS(I14))))+$B$6/$B$5))))) -> 30.004439 | O14: =IF(N14="","",SIGN(H14)*MIN(ABS(H14),ABS(I14))-N14) -> 3.4955611
A15: Pos5 | H15: =IF(COUNT(D15:E15)=0,"",AVERAGE(D15:E15)) | I15: =IF(COUNT(F15:G15)=0,"",AVERAGE(F15:G15)) | J15: =IF(OR(H15="",I15=""),"",IF(ABS(H15+I15)<0.05,0,DEGREES(ATAN(2/(1/TAN(RADIANS(H15))+1/TAN(RADIANS(I15))))))) | K15: =IF(OR(J15="",C15=""),"",J15-C15) | L15: =IF(COUNT(D15:E15)<2,"",D15-E15) | M15: =IF(COUNT(F15:G15)<2,"",F15-G15) | N15: =IF(OR(H15="",I15=""),"",IF(ABS(H15)<0.05,0,SIGN(H15)*DEGREES(ATAN(1/(1/TAN(RADIANS(MAX(ABS(H15),ABS(I15))))+$B$6/$B$5))))) | O15: =IF(N15="","",SIGN(H15)*MIN(ABS(H15),ABS(I15))-N15)
A16: Pos6 | H16: =IF(COUNT(D16:E16)=0,"",AVERAGE(D16:E16)) | I16: =IF(COUNT(F16:G16)=0,"",AVERAGE(F16:G16)) | J16: =IF(OR(H16="",I16=""),"",IF(ABS(H16+I16)<0.05,0,DEGREES(ATAN(2/(1/TAN(RADIANS(H16))+1/TAN(RADIANS(I16))))))) | K16: =IF(OR(J16="",C16=""),"",J16-C16) | L16: =IF(COUNT(D16:E16)<2,"",D16-E16) | M16: =IF(COUNT(F16:G16)<2,"",F16-G16) | N16: =IF(OR(H16="",I16=""),"",IF(ABS(H16)<0.05,0,SIGN(H16)*DEGREES(ATAN(1/(1/TAN(RADIANS(MAX(ABS(H16),ABS(I16))))+$B$6/$B$5))))) | O16: =IF(N16="","",SIGN(H16)*MIN(ABS(H16),ABS(I16))-N16)
A17: Pos7 | H17: =IF(COUNT(D17:E17)=0,"",AVERAGE(D17:E17)) | I17: =IF(COUNT(F17:G17)=0,"",AVERAGE(F17:G17)) | J17: =IF(OR(H17="",I17=""),"",IF(ABS(H17+I17)<0.05,0,DEGREES(ATAN(2/(1/TAN(RADIANS(H17))+1/TAN(RADIANS(I17))))))) | K17: =IF(OR(J17="",C17=""),"",J17-C17) | L17: =IF(COUNT(D17:E17)<2,"",D17-E17) | M17: =IF(COUNT(F17:G17)<2,"",F17-G17) | N17: =IF(OR(H17="",I17=""),"",IF(ABS(H17)<0.05,0,SIGN(H17)*DEGREES(ATAN(1/(1/TAN(RADIANS(MAX(ABS(H17),ABS(I17))))+$B$6/$B$5))))) | O17: =IF(N17="","",SIGN(H17)*MIN(ABS(H17),ABS(I17))-N17)
A18: Pos8 | H18: =IF(COUNT(D18:E18)=0,"",AVERAGE(D18:E18)) | I18: =IF(COUNT(F18:G18)=0,"",AVERAGE(F18:G18)) | J18: =IF(OR(H18="",I18=""),"",IF(ABS(H18+I18)<0.05,0,DEGREES(ATAN(2/(1/TAN(RADIANS(H18))+1/TAN(RADIANS(I18))))))) | K18: =IF(OR(J18="",C18=""),"",J18-C18) | L18: =IF(COUNT(D18:E18)<2,"",D18-E18) | M18: =IF(COUNT(F18:G18)<2,"",F18-G18) | N18: =IF(OR(H18="",I18=""),"",IF(ABS(H18)<0.05,0,SIGN(H18)*DEGREES(ATAN(1/(1/TAN(RADIANS(MAX(ABS(H18),ABS(I18))))+$B$6/$B$5))))) | O18: =IF(N18="","",SIGN(H18)*MIN(ABS(H18),ABS(I18))-N18)
A19: Pos9 | H19: =IF(COUNT(D19:E19)=0,"",AVERAGE(D19:E19)) | I19: =IF(COUNT(F19:G19)=0,"",AVERAGE(F19:G19)) | J19: =IF(OR(H19="",I19=""),"",IF(ABS(H19+I19)<0.05,0,DEGREES(ATAN(2/(1/TAN(RADIANS(H19))+1/TAN(RADIANS(I19))))))) | K19: =IF(OR(J19="",C19=""),"",J19-C19) | L19: =IF(COUNT(D19:E19)<2,"",D19-E19) | M19: =IF(COUNT(F19:G19)<2,"",F19-G19) | N19: =IF(OR(H19="",I19=""),"",IF(ABS(H19)<0.05,0,SIGN(H19)*DEGREES(ATAN(1/(1/TAN(RADIANS(MAX(ABS(H19),ABS(I19))))+$B$6/$B$5))))) | O19: =IF(N19="","",SIGN(H19)*MIN(ABS(H19),ABS(I19))-N19)
A21: Key figures
A22: Max. hysteresis (play) [°] | C22: =IF(COUNT(L11:M19)=0,"",MAX(MAX(L11:M19),-MIN(L11:M19)))
A23: Mean |deviation| [°] | C23: =IF(COUNT(K11:K19)=0,"",SUMPRODUCT(ABS(N(+K11:K19)))/COUNT(K11:K19)) -> 4.295528
A24: Max. |deviation| [°] | C24: =IF(COUNT(K11:K19)=0,"",MAX(MAX(K11:K19),-MIN(K11:K19))) -> 8.1084256
A26: Previous measurement series for comparison (from Messreihen_Motor_Servo.xlsx)
A27: Pos | B27: Target [°] | C27: LEGO forward | D27: LEGO return | E27: Direct forward | F27: Direct return | G27: LEGO hysteresis | H27: Direct hysteresis
A28: Pos1 | B28: -35 | C28: -32.5 | D28: -31.9 | E28: -34.8 | F28: -34.8 | G28: =C28-D28 -> -0.6 | H28: =E28-F28 -> 0
A29: Pos2 | B29: -30 | C29: -27 | D29: -31 | E29: -29.7 | F29: -30.2 | G29: =C29-D29 -> 4 | H29: =E29-F29 -> 0.5
A30: Pos3 | B30: -20 | C30: -16.5 | D30: -21.5 | E30: -19.8 | F30: -20.3 | G30: =C30-D30 -> 5 | H30: =E30-F30 -> 0.5
A31: Pos4 | B31: -10 | C31: -6 | D31: -12 | E31: -9.7 | F31: -10.1 | G31: =C31-D31 -> 6 | H31: =E31-F31 -> 0.4
A32: Pos5 | B32: 0 | C32: 3.5 | D32: -3.5 | E32: 0.2 | F32: -0.2 | G32: =C32-D32 -> 7 | H32: =E32-F32 -> 0.4
A33: Pos6 | B33: 10 | C33: 13 | D33: 7.5 | E33: 10.1 | F33: 9.8 | G33: =C33-D33 -> 5.5 | H33: =E33-F33 -> 0.3
A34: Pos7 | B34: 20 | C34: 22.5 | D34: 17 | E34: 20.2 | F34: 19.7 | G34: =C34-D34 -> 5.5 | H34: =E34-F34 -> 0.5
A35: Pos8 | B35: 30 | C35: 31.5 | D35: 28 | E35: 30.1 | F35: 29.6 | G35: =C35-D35 -> 3.5 | H35: =E35-F35 -> 0.5
A36: Pos9 | B36: 35 | C36: 34 | D36: 34 | E36: 34.9 | F36: 34.9 | G36: =C36-D36 -> 0 | H36: =E36-F36 -> 0
A38: Servo step response (T13)
A39: t [s] | B39: Target position | C39: Actual position (SC09 feedback)
A40: 0 | B40: 0 | C40: 0
A41: 0.04 | B41: -97.9 | C41: 0
A42: 0.08 | B42: -97.9 | C42: -9.8
A43: 0.12 | B43: -97.9 | C43: -22.8
A44: 0.16 | B44: -97.9 | C44: -35.9
A45: 0.2 | B45: -97.9 | C45: -49
...

Sheet Ackermann_CAD
A1: Ackermann analysis from CAD (R02/R03)
A2: δ_outer (linkage) = calculated numerically from the CAD joint points (four-bar: knuckle – steering arm – tie rod). At 58° inner this gives 36.5° outer, which matches the Fusion values (58° / 36°).
A4: Wheelbase L [mm] | B4: =Mass_CoG!B8 -> 102
A5: Kingpin distance k [mm] | B5: 59.3
A6: Steering arm length [mm] | B6: 15.55
A7: Steering arm angle left [°] | B7: 15.3
A8: Steering arm angle right [°] | B8: 16
A9: Ideal steering arm angle atan(k/2 / L) [°] | B9: =DEGREES(ATAN(B5/2/B4)) -> 16.208423
A10: Tie-rod length (joint distance) [mm] | B10: 50.9
A11: Result: the arm angles (15.3° / 16.0°) are almost exactly at the ideal value of 16.2°. By the classic design rule this is ≈ 100 % Ackermann. Over the full steering range, however, the linkage deviates: up to approx. 45° the outer wheel steers slightly too far (below 100 %), near full lock too little (above 100 %).
A13: δ_inner [°] | B13: δ_outer linkage, left turn [°] | C13: δ_outer linkage, right turn [°] | D13: δ_outer ideal [°] | E13: Linkage − ideal error [°] | F13: Ackermann % (local) | G13: R rear-axle centre from inner wheel [mm] | H13: R from outer wheel [mm] | I13: Spread of the radii [mm]
A14: 0 | B14: 0 | C14: 0 | D14: =IF(A14=0,0,DEGREES(ATAN(1/(1/TAN(RADIANS(A14))+$B$5/$B$4)))) -> 0 | E14: =B14-D14 -> 0 | F14: =IF(A14-D14=0,"",(A14-B14)/(A14-D14)) | G14: =IF(A14=0,"",$B$4/TAN(RADIANS(A14))+$B$5/2) | H14: =IF(B14=0,"",$B$4/TAN(RADIANS(B14))-$B$5/2) | I14: =IF(G14="","",H14-G14)
A15: 2 | B15: 1.98 | C15: 1.98 | D15: =IF(A15=0,0,DEGREES(ATAN(1/(1/TAN(RADIANS(A15))+$B$5/$B$4)))) -> 1.9602353 | E15: =B15-D15 -> 0.019764654 | F15: =IF(A15-D15=0,"",(A15-B15)/(A15-D15)) -> 0.50295923 | G15: =IF(A15=0,"",$B$4/TAN(RADIANS(A15))+$B$5/2) -> 2950.5478 | H15: =IF(B15=0,"",$B$4/TAN(RADIANS(B15))-$B$5/2) -> 2920.7757 | I15: =IF(G15="","",H15-G15) -> -29.772121
A16: 4 | B16: 3.91 | C16: 3.91 | D16: =IF(A16=0,0,DEGREES(ATAN(1/(1/TAN(RADIANS(A16))+$B$5/$B$4)))) -> 3.8442165 | E16: =B16-D16 -> 0.065783524 | F16: =IF(A16-D16=0,"",(A16-B16)/(A16-D16)) -> 0.57772477 | G16: =IF(A16=0,"",$B$4/TAN(RADIANS(A16))+$B$5/2) -> 1488.318 | H16: =IF(B16=0,"",$B$4/TAN(RADIANS(B16))-$B$5/2) -> 1462.7015 | I16: =IF(G16="","",H16-G16) -> -25.616411
A17: 6 | B17: 5.8 | C17: 5.8 | D17: =IF(A17=0,0,DEGREES(ATAN(1/(1/TAN(RADIANS(A17))+$B$5/$B$4)))) -> 5.656793 | E17: =B17-D17 -> 0.14320704 | F17: =IF(A17-D17=0,"",(A17-B17)/(A17-D17)) -> 0.58273863 | G17: =IF(A17=0,"",$B$4/TAN(RADIANS(A17))+$B$5/2) -> 1000.1152 | H17: =IF(B17=0,"",$B$4/TAN(RADIANS(B17))-$B$5/2) -> 974.52129 | I17: =IF(G17="","",H17-G17) -> -25.593884
A18: 8 | B18: 7.65 | C18: 7.65 | D18: =IF(A18=0,0,DEGREES(ATAN(1/(1/TAN(RADIANS(A18))+$B$5/$B$4)))) -> 7.4026919 | E18: =B18-D18 -> 0.24730811 | F18: =IF(A18-D18=0,"",(A18-B18)/(A18-D18)) -> 0.58596224 | G18: =IF(A18=0,"",$B$4/TAN(RADIANS(A18))+$B$5/2) -> 755.41771 | H18: =IF(B18=0,"",$B$4/TAN(RADIANS(B18))-$B$5/2) -> 729.74872 | I18: =IF(G18="","",H18-G18) -> -25.668991
A19: 10 | B19: 9.45 | C19: 9.45 | D19: =IF(A19=0,0,DEGREES(ATAN(1/(1/TAN(RADIANS(A19))+$B$5/$B$4)))) -> 9.0864823 | E19: =B19-D19 -> 0.36351768 | F19: =IF(A19-D19=0,"",(A19-B19)/(A19-D19)) -> 0.60206826 | G19: =IF(A19=0,"",$B$4/TAN(RADIANS(A19))+$B$5/2) -> 608.12075 | H19: =IF(B19=0,"",$B$4/TAN(RADIANS(B19))-$B$5/2) -> 583.1627 | I19: =IF(G19="","",H19-G19) -> -24.958049
A20: 12 | B20: 11.22 | C20: 11.21 | D20: =IF(A20=0,0,DEGREES(ATAN(1/(1/TAN(RADIANS(A20))+$B$5/$B$4)))) -> 10.712552 | E20: =B20-D20 -> 0.5074479 | F20: =IF(A20-D20=0,"",(A20-B20)/(A20-D20)) -> 0.60584976 | G20: =IF(A20=0,"",$B$4/TAN(RADIANS(A20))+$B$5/2) -> 509.52227 | H20: =IF(B20=0,"",$B$4/TAN(RADIANS(B20))-$B$5/2) -> 484.54556 | I20: =IF(G20="","",H20-G20) -> -24.976714
A21: 14 | B21: 12.94 | C21: 12.93 | D21: =IF(A21=0,0,DEGREES(ATAN(1/(1/TAN(RADIANS(A21))+$B$5/$B$4)))) -> 12.285094 | E21: =B21-D21 -> 0.65490561 | F21: =IF(A21-D21=0,"",(A21-B21)/(A21-D21)) -> 0.61810982 | G21: =IF(A21=0,"",$B$4/TAN(RADIANS(A21))+$B$5/2) -> 438.74966 | H21: =IF(B21=0,"",$B$4/TAN(RADIANS(B21))-$B$5/2) -> 414.28099 | I21: =IF(G21="","",H21-G21) -> -24.46867
A22: 16 | B22: 14.61 | C22: 14.61 | D22: =IF(A22=0,0,DEGREES(ATAN(1/(1/TAN(RADIANS(A22))+$B$5/$B$4)))) -> 13.808102 | E22: =B22-D22 -> 0.80189834 | F22: =IF(A22-D22=0,"",(A22-B22)/(A22-D22)) -> 0.6341535 | G22: =IF(A22=0,"",$B$4/TAN(RADIANS(A22))+$B$5/2) -> 385.36627 | H22: =IF(B22=0,"",$B$4/TAN(RADIANS(B22))-$B$5/2) -> 361.65404 | I22: =IF(G22="","",H22-G22) -> -23.712235
A23: 18 | B23: 16.25 | C23: 16.24 | D23: =IF(A23=0,0,DEGREES(ATAN(1/(1/TAN(RADIANS(A23))+$B$5/$B$4)))) -> 15.285365 | E23: =B23-D23 -> 0.9646345 | F23: =IF(A23-D23=0,"",(A23-B23)/(A23-D23)) -> 0.644654 | G23: =IF(A23=0,"",$B$4/TAN(RADIANS(A23))+$B$5/2) -> 343.57372 | H23: =IF(B23=0,"",$B$4/TAN(RADIANS(B23))-$B$5/2) -> 320.29615 | I23: =IF(G23="","",H23-G23) -> -23.277574
A24: 20 | B24: 17.83 | C24: 17.82 | D24: =IF(A24=0,0,DEGREES(ATAN(1/(1/TAN(RADIANS(A24))+$B$5/$B$4)))) -> 16.720481 | E24: =B24-D24 -> 1.1095195 | F24: =IF(A24-D24=0,"",(A24-B24)/(A24-D24)) -> 0.66168231 | G24: =IF(A24=0,"",$B$4/TAN(RADIANS(A24))+$B$5/2) -> 309.8927 | H24: =IF(B24=0,"",$B$4/TAN(RADIANS(B24))-$B$5/2) -> 287.47223 | I24: =IF(G24="","",H24-G24) -> -22.420471
A25: 22 | B25: 19.37 | C25: 19.36 | D25: =IF(A25=0,0,DEGREES(ATAN(1/(1/TAN(RADIANS(A25))+$B$5/$B$4)))) -> 18.116851 | E25: =B25-D25 -> 1.2531485 | F25: =IF(A25-D25=0,"",(A25-B25)/(A25-D25)) -> 0.67728545 | G25: =IF(A25=0,"",$B$4/TAN(RADIANS(A25))+$B$5/2) -> 282.10886 | H25: =IF(B25=0,"",$B$4/TAN(RADIANS(B25))-$B$5/2) -> 260.47948 | I25: =IF(G25="","",H25-G25) -> -21.629377
... A43: 58 | B43: 36.53 | C43: 36.25 | D43: =IF(A43=0,0,DEGREES(ATAN(1/(1/TAN(RADIANS(A43))+$B$5/$B$4)))) -> 39.659448 | E43: =B43-D43 -> -3.1294484 | F43: =IF(A43-D43=0,"",(A43-B43)/(A43-D43)) -> 1.17063 | G43: =IF(A43=0,"",$B$4/TAN(RADIANS(A43))+$B$5/2) -> 93.386674 | H43: =IF(B43=0,"",$B$4/TAN(RADIANS(B43))-$B$5/2) -> 108.04425 | I43: =IF(G43="","",H43-G43) -> 14.657575
A45: Theoretical turning circle (full lock, no slip)
A46: R rear-axle centre at 58° inner [mm] | B46: =G43 -> 93.386674
A47: Radius outer front wheel (wheel centre) [mm] | B47: =SQRT((B46+Mass_CoG!B9/2)^2+B4^2) -> 174.42041
A48: Turning circle diameter outer (wheel centre + half tyre width 7.5 mm) [mm] | B48: =2*(B47+7.5) -> 363.84082
A49: Note: the linkage values are calculated from CAD points (Python). If the steering changes, the STEP file has to be re-evaluated and columns B/C recalculated.

Sheet Radius_v
A1: Turning radius per steering command and speed (T06/T09, R03/R10)
A2: One constant steering command per row, drive 2 full circles. v and ψ̇ each as the mean over the steady-state part (omit the first half lap).
A4: Wheelbase L [mm] | B4: =Mass_CoG!B8 -> 102
A6: Steering command | B6: Direction (L/R) | C6: v target [m/s] | D6: v measured (encoder) [m/s] | E6: ψ̇ measured (IMU) [rad/s] | F6: R = v/ψ̇ [mm] | G6: Circle Ø tape measure [mm] (optional) | H6: R tape measure [mm] | I6: δ_eff = atan(L/R) [°] | J6: δ_static from Steering_Target_Actual [°] | K6: Understeer δ_stat − δ_eff [°] | L6: a_y = v²/R [m/s²]
A7: 50 | B7: L | C7: 0.2 | D7: 0.21 | E7: 0.62
A8: 100 | B8: L | C8: 0.2 | D8: 0.199 | E8: 0.813 | F8: =IF(OR(D8="",E8="",E8=0),"",1000*D8/ABS(E8)) -> 244.77245 | G8: 488 | H8: =IF(G8="","",G8/2) -> 244 | I8: =IF(F8="","",DEGREES(ATAN($B$4/F8))) -> 22.622155 | J8: =IF(A8="","",IFERROR(ABS(INDEX(Steering_Target_Actual!$J$11:$J$19,MATCH(A8,Steering_Target_Actual!$B$11:$B$19,0))),"")) -> 43.906735 | K8: =IF(OR(I8="",J8=""),"",J8-I8) -> 21.28458 | L8: =IF(OR(F8="",D8=""),"",D8^2/(F8/1000)) -> 0.161787
A9: 75 | B9: L | C9: 0.2 | D9: 0.199 | E9: 0.52 | F9: =IF(OR(D9="",E9="",E9=0),"",1000*D9/ABS(E9)) -> 382.69231 | H9: =IF(G9="","",G9/2) | I9: =IF(F9="","",DEGREES(ATAN($B$4/F9))) -> 14.924249 | J9: =IF(A9="","",IFERROR(ABS(INDEX(Steering_Target_Actual!$J$11:$J$19,MATCH(A9,Steering_Target_Actual!$B$11:$B$19,0))),"")) -> 30.957508 | K9: =IF(OR(I9="",J9=""),"",J9-I9) -> 16.033259 | L9: =IF(OR(F9="",D9=""),"",D9^2/(F9/1000)) -> 0.10348
A10: 50 | B10: L | C10: 0.2 | D10: 0.199 | E10: 0.311 | F10: =IF(OR(D10="",E10="",E10=0),"",1000*D10/ABS(E10)) -> 639.87138 | G10: 1281 | H10: =IF(G10="","",G10/2) -> 640.5 | I10: =IF(F10="","",DEGREES(ATAN($B$4/F10))) -> 9.0571475 | J10: =IF(A10="","",IFERROR(ABS(INDEX(Steering_Target_Actual!$J$11:$J$19,MATCH(A10,Steering_Target_Actual!$B$11:$B$19,0))),"")) -> 18.592975 | K10: =IF(OR(I10="",J10=""),"",J10-I10) -> 9.5358272 | L10: =IF(OR(F10="",D10=""),"",D10^2/(F10/1000)) -> 0.061889
A11: 25 | B11: L | C11: 0.2 | D11: 0.199 | E11: 0.147 | F11: =IF(OR(D11="",E11="",E11=0),"",1000*D11/ABS(E11)) -> 1353.7415 | H11: =IF(G11="","",G11/2) | I11: =IF(F11="","",DEGREES(ATAN($B$4/F11))) -> 4.3089081 | J11: =IF(A11="","",IFERROR(ABS(INDEX(Steering_Target_Actual!$J$11:$J$19,MATCH(A11,Steering_Target_Actual!$B$11:$B$19,0))),"")) -> 8.6714967 | K11: =IF(OR(I11="",J11=""),"",J11-I11) -> 4.3625887 | L11: =IF(OR(F11="",D11=""),"",D11^2/(F11/1000)) -> 0.029253
A12: -25 | B12: R | C12: 0.2 | D12: 0.198 | E12: 0.22 | F12: =IF(OR(D12="",E12="",E12=0),"",1000*D12/ABS(E12)) -> 900 | H12: =IF(G12="","",G12/2) | I12: =IF(F12="","",DEGREES(ATAN($B$4/F12))) -> 6.4659321 | J12: =IF(A12="","",IFERROR(ABS(INDEX(Steering_Target_Actual!$J$11:$J$19,MATCH(A12,Steering_Target_Actual!$B$11:$B$19,0))),"")) -> 11.813277 | K12: =IF(OR(I12="",J12=""),"",J12-I12) -> 5.3473447 | L12: =IF(OR(F12="",D12=""),"",D12^2/(F12/1000)) -> 0.04356
A13: -50 | B13: R | C13: 0.2 | D13: 0.199 | E13: 0.456 | F13: =IF(OR(D13="",E13="",E13=0),"",1000*D13/ABS(E13)) -> 436.40351 | G13: 864 | H13: =IF(G13="","",G13/2) -> 432 | I13: =IF(F13="","",DEGREES(ATAN($B$4/F13))) -> 13.155501 | J13: =IF(A13="","",IFERROR(ABS(INDEX(Steering_Target_Actual!$J$11:$J$19,MATCH(A13,Steering_Target_Actual!$B$11:$B$19,0))),"")) -> 24.89293 | K13: =IF(OR(I13="",J13=""),"",J13-I13) -> 11.737429 | L13: =IF(OR(F13="",D13=""),"",D13^2/(F13/1000)) -> 0.090744
A14: -75 | B14: R | C14: 0.2 | D14: 0.199 | E14: 0.717 | F14: =IF(OR(D14="",E14="",E14=0),"",1000*D14/ABS(E14)) -> 277.54533 | H14: =IF(G14="","",G14/2) | I14: =IF(F14="","",DEGREES(ATAN($B$4/F14))) -> 20.178761 | J14: =IF(A14="","",IFERROR(ABS(INDEX(Steering_Target_Actual!$J$11:$J$19,MATCH(A14,Steering_Target_Actual!$B$11:$B$19,0))),"")) -> 37.46179 | K14: =IF(OR(I14="",J14=""),"",J14-I14) -> 17.283029 | L14: =IF(OR(F14="",D14=""),"",D14^2/(F14/1000)) -> 0.142683
A15: -100 | B15: R | C15: 0.2 | D15: 0.2 | E15: 0.934 | F15: =IF(OR(D15="",E15="",E15=0),"",1000*D15/ABS(E15)) -> 214.13276 | G15: 436 | H15: =IF(G15="","",G15/2) -> 218 | I15: =IF(F15="","",DEGREES(ATAN($B$4/F15))) -> 25.470328 | J15: =IF(A15="","",IFERROR(ABS(INDEX(Steering_Target_Actual!$J$11:$J$19,MATCH(A15,Steering_Target_Actual!$B$11:$B$19,0))),"")) -> 45.023564 | K15: =IF(OR(I15="",J15=""),"",J15-I15) -> 19.553236 | L15: =IF(OR(F15="",D15=""),"",D15^2/(F15/1000)) -> 0.1868
A16: 100 | B16: L | C16: 0.35 | D16: 0.351 | E16: 1.393 | F16: =IF(OR(D16="",E16="",E16=0),"",1000*D16/ABS(E16)) -> 251.97416 | H16: =IF(G16="","",G16/2) | I16: =IF(F16="","",DEGREES(ATAN($B$4/F16))) -> 22.038271 | J16: =IF(A16="","",IFERROR(ABS(INDEX(Steering_Target_Actual!$J$11:$J$19,MATCH(A16,Steering_Target_Actual!$B$11:$B$19,0))),"")) -> 43.906735 | K16: =IF(OR(I16="",J16=""),"",J16-I16) -> 21.868464 | L16: =IF(OR(F16="",D16=""),"",D16^2/(F16/1000)) -> 0.488943
A17: 50 | B17: L | C17: 0.35 | D17: 0.351 | E17: 0.536 | F17: =IF(OR(D17="",E17="",E17=0),"",1000*D17/ABS(E17)) -> 654.85075 | H17: =IF(G17="","",G17/2) | I17: =IF(F17="","",DEGREES(ATAN($B$4/F17))) -> 8.8532895 | J17: =IF(A17="","",IFERROR(ABS(INDEX(Steering_Target_Actual!$J$11:$J$19,MATCH(A17,Steering_Target_Actual!$B$11:$B$19,0))),"")) -> 18.592975 | K17: =IF(OR(I17="",J17=""),"",J17-I17) -> 9.7396852 | L17: =IF(OR(F17="",D17=""),"",D17^2/(F17/1000)) -> 0.188136
A18: -50 | B18: R | C18: 0.35 | D18: 0.353 | E18: 0.786 | F18: =IF(OR(D18="",E18="",E18=0),"",1000*D18/ABS(E18)) -> 449.10941 | H18: =IF(G18="","",G18/2) | I18: =IF(F18="","",DEGREES(ATAN($B$4/F18))) -> 12.795735 | J18: =IF(A18="","",IFERROR(ABS(INDEX(Steering_Target_Actual!$J$11:$J$19,MATCH(A18,Steering_Target_Actual!$B$11:$B$19,0))),"")) -> 24.89293 | K18: =IF(OR(I18="",J18=""),"",J18-I18) -> 12.097195 | L18: =IF(OR(F18="",D18=""),"",D18^2/(F18/1000)) -> 0.277458
A19: -100 | B19: R | C19: 0.35 | D19: 0.349 | E19: 1.548 | F19: =IF(OR(D19="",E19="",E19=0),"",1000*D19/ABS(E19)) -> 225.4522 | H19: =IF(G19="","",G19/2) | I19: =IF(F19="","",DEGREES(ATAN($B$4/F19))) -> 24.343141 | J19: =IF(A19="","",IFERROR(ABS(INDEX(Steering_Target_Actual!$J$11:$J$19,MATCH(A19,Steering_Target_Actual!$B$11:$B$19,0))),"")) -> 45.023564 | K19: =IF(OR(I19="",J19=""),"",J19-I19) -> 20.680423 | L19: =IF(OR(F19="",D19=""),"",D19^2/(F19/1000)) -> 0.540252
A20: 100 | B20: L | C20: 0.5 | D20: 0.496 | E20: 1.88 | F20: =IF(OR(D20="",E20="",E20=0),"",1000*D20/ABS(E20)) -> 263.82979 | H20: =IF(G20="","",G20/2) | I20: =IF(F20="","",DEGREES(ATAN($B$4/F20))) -> 21.137145 | J20: =IF(A20="","",IFERROR(ABS(INDEX(Steering_Target_Actual!$J$11:$J$19,MATCH(A20,Steering_Target_Actual!$B$11:$B$19,0))),"")) -> 43.906735 | K20: =IF(OR(I20="",J20=""),"",J20-I20) -> 22.76959 | L20: =IF(OR(F20="",D20=""),"",D20^2/(F20/1000)) -> 0.93248
A21: 50 | B21: L | C21: 0.5 | D21: 0.503 | E21: 0.749 | F21: =IF(OR(D21="",E21="",E21=0),"",1000*D21/ABS(E21)) -> 671.56208 | H21: =IF(G21="","",G21/2) | I21: =IF(F21="","",DEGREES(ATAN($B$4/F21))) -> 8.636345 | J21: =IF(A21="","",IFERROR(ABS(INDEX(Steering_Target_Actual!$J$11:$J$19,MATCH(A21,Steering_Target_Actual!$B$11:$B$19,0))),"")) -> 18.592975 | K21: =IF(OR(I21="",J21=""),"",J21-I21) -> 9.9566297 | L21: =IF(OR(F21="",D21=""),"",D21^2/(F21/1000)) -> 0.376747
A22: -100 | B22: R | C22: 0.5 | D22: 0.5 | E22: 2.185 | F22: =IF(OR(D22="",E22="",E22=0),"",1000*D22/ABS(E22)) -> 228.83295 | H22: =IF(G22="","",G22/2) | I22: =IF(F22="","",DEGREES(ATAN($B$4/F22))) -> 24.024445 | J22: =IF(A22="","",IFERROR(ABS(INDEX(Steering_Target_Actual!$J$11:$J$19,MATCH(A22,Steering_Target_Actual!$B$11:$B$19,0))),"")) -> 45.023564 | K22: =IF(OR(I22="",J22=""),"",J22-I22) -> 20.999119 | L22: =IF(OR(F22="",D22=""),"",D22^2/(F22/1000)) -> 1.0925
A23: 100 | B23: L | C23: 0.75 | D23: 0.753 | E23: 2.578 | F23: =IF(OR(D23="",E23="",E23=0),"",1000*D23/ABS(E23)) -> 292.08689 | H23: =IF(G23="","",G23/2) | I23: =IF(F23="","",DEGREES(ATAN($B$4/F23))) -> 19.249771 | J23: =IF(A23="","",IFERROR(ABS(INDEX(Steering_Target_Actual!$J$11:$J$19,MATCH(A23,Steering_Target_Actual!$B$11:$B$19,0))),"")) -> 43.906735 | K23: =IF(OR(I23="",J23=""),"",J23-I23) -> 24.656963 | L23: =IF(OR(F23="",D23=""),"",D23^2/(F23/1000)) -> 1.941234
A24: 50 | B24: L | C24: 0.75 | D24: 0.751 | E24: 1.005 | F24: =IF(OR(D24="",E24="",E24=0),"",1000*D24/ABS(E24)) -> 747.26368 | H24: =IF(G24="","",G24/2) | I24: =IF(F24="","",DEGREES(ATAN($B$4/F24))) -> 7.772724 | J24: =IF(A24="","",IFERROR(ABS(INDEX(Steering_Target_Actual!$J$11:$J$19,MATCH(A24,Steering_Target_Actual!$B$11:$B$19,0))),"")) -> 18.592975 | K24: =IF(OR(I24="",J24=""),"",J24-I24) -> 10.820251 | L24: =IF(OR(F24="",D24=""),"",D24^2/(F24/1000)) -> 0.754755
A25: -100 | B25: R | C25: 0.75 | D25: 0.747 | E25: 2.897 | F25: =IF(OR(D25="",E25="",E25=0),"",1000*D25/ABS(E25)) -> 257.85295 | H25: =IF(G25="","",G25/2) | I25: =IF(F25="","",DEGREES(ATAN($B$4/F25))) -> 21.582478 | J25: =IF(A25="","",IFERROR(ABS(INDEX(Steering_Target_Actual!$J$11:$J$19,MATCH(A25,Steering_Target_Actual!$B$11:$B$19,0))),"")) -> 45.023564 | K25: =IF(OR(I25="",J25=""),"",J25-I25) -> 23.441086 | L25: =IF(OR(F25="",D25=""),"",D25^2/(F25/1000)) -> 2.164059
A26: 25 | B26: L | C26: 0.75 | D26: 0.751 | E26: 0.478 | F26: =IF(OR(D26="",E26="",E26=0),"",1000*D26/ABS(E26)) -> 1571.1297 | H26: =IF(G26="","",G26/2) | I26: =IF(F26="","",DEGREES(ATAN($B$4/F26))) -> 3.7145116 | J26: =IF(A26="","",IFERROR(ABS(INDEX(Steering_Target_Actual!$J$11:$J$19,MATCH(A26,Steering_Target_Actual!$B$11:$B$19,0))),"")) -> 8.6714967 | K26: =IF(OR(I26="",J26=""),"",J26-I26) -> 4.9569851 | L26: =IF(OR(F26="",D26=""),"",D26^2/(F26/1000)) -> 0.358978
F27: =IF(OR(D27="",E27="",E27=0),"",1000*D27/ABS(E27)) | H27: =IF(G27="","",G27/2) | I27: =IF(F27="","",DEGREES(ATAN($B$4/F27))) | J27: =IF(A27="","",IFERROR(ABS(INDEX(Steering_Target_Actual!$J$11:$J$19,MATCH(A27,Steering_Target_Actual!$B$11:$B$19,0))),"")) | K27: =IF(OR(I27="",J27=""),"",J27-I27) | L27: =IF(OR(F27="",D27=""),"",D27^2/(F27/1000))
F28: =IF(OR(D28="",E28="",E28=0),"",1000*D28/ABS(E28)) | H28: =IF(G28="","",G28/2) | I28: =IF(F28="","",DEGREES(ATAN($B$4/F28))) | J28: =IF(A28="","",IFERROR(ABS(INDEX(Steering_Target_Actual!$J$11:$J$19,MATCH(A28,Steering_Target_Actual!$B$11:$B$19,0))),"")) | K28: =IF(OR(I28="",J28=""),"",J28-I28) | L28: =IF(OR(F28="",D28=""),"",D28^2/(F28/1000))
F29: =IF(OR(D29="",E29="",E29=0),"",1000*D29/ABS(E29)) | H29: =IF(G29="","",G29/2) | I29: =IF(F29="","",DEGREES(ATAN($B$4/F29))) | J29: =IF(A29="","",IFERROR(ABS(INDEX(Steering_Target_Actual!$J$11:$J$19,MATCH(A29,Steering_Target_Actual!$B$11:$B$19,0))),"")) | K29: =IF(OR(I29="",J29=""),"",J29-I29) | L29: =IF(OR(F29="",D29=""),"",D29^2/(F29/1000))
F30: =IF(OR(D30="",E30="",E30=0),"",1000*D30/ABS(E30)) | H30: =IF(G30="","",G30/2) | I30: =IF(F30="","",DEGREES(ATAN($B$4/F30))) | J30: =IF(A30="","",IFERROR(ABS(INDEX(Steering_Target_Actual!$J$11:$J$19,MATCH(A30,Steering_Target_Actual!$B$11:$B$19,0))),"")) | K30: =IF(OR(I30="",J30=""),"",J30-I30) | L30: =IF(OR(F30="",D30=""),"",D30^2/(F30/1000))
F31: =IF(OR(D31="",E31="",E31=0),"",1000*D31/ABS(E31)) | H31: =IF(G31="","",G31/2) | I31: =IF(F31="","",DEGREES(ATAN($B$4/F31))) | J31: =IF(A31="","",IFERROR(ABS(INDEX(Steering_Target_Actual!$J$11:$J$19,MATCH(A31,Steering_Target_Actual!$B$11:$B$19,0))),"")) | K31: =IF(OR(I31="",J31=""),"",J31-I31) | L31: =IF(OR(F31="",D31=""),"",D31^2/(F31/1000))
F32: =IF(OR(D32="",E32="",E32=0),"",1000*D32/ABS(E32)) | H32: =IF(G32="","",G32/2) | I32: =IF(F32="","",DEGREES(ATAN($B$4/F32))) | J32: =IF(A32="","",IFERROR(ABS(INDEX(Steering_Target_Actual!$J$11:$J$19,MATCH(A32,Steering_Target_Actual!$B$11:$B$19,0))),"")) | K32: =IF(OR(I32="",J32=""),"",J32-I32) | L32: =IF(OR(F32="",D32=""),"",D32^2/(F32/1000))
F33: =IF(OR(D33="",E33="",E33=0),"",1000*D33/ABS(E33)) | H33: =IF(G33="","",G33/2) | I33: =IF(F33="","",DEGREES(ATAN($B$4/F33))) | J33: =IF(A33="","",IFERROR(ABS(INDEX(Steering_Target_Actual!$J$11:$J$19,MATCH(A33,Steering_Target_Actual!$B$11:$B$19,0))),"")) | K33: =IF(OR(I33="",J33=""),"",J33-I33) | L33: =IF(OR(F33="",D33=""),"",D33^2/(F33/1000))
F34: =IF(OR(D34="",E34="",E34=0),"",1000*D34/ABS(E34)) | H34: =IF(G34="","",G34/2) | I34: =IF(F34="","",DEGREES(ATAN($B$4/F34))) | J34: =IF(A34="","",IFERROR(ABS(INDEX(Steering_Target_Actual!$J$11:$J$19,MATCH(A34,Steering_Target_Actual!$B$11:$B$19,0))),"")) | K34: =IF(OR(I34="",J34=""),"",J34-I34) | L34: =IF(OR(F34="",D34=""),"",D34^2/(F34/1000))
F35: =IF(OR(D35="",E35="",E35=0),"",1000*D35/ABS(E35)) | H35: =IF(G35="","",G35/2) | I35: =IF(F35="","",DEGREES(ATAN($B$4/F35))) | J35: =IF(A35="","",IFERROR(ABS(INDEX(Steering_Target_Actual!$J$11:$J$19,MATCH(A35,Steering_Target_Actual!$B$11:$B$19,0))),"")) | K35: =IF(OR(I35="",J35=""),"",J35-I35) | L35: =IF(OR(F35="",D35=""),"",D35^2/(F35/1000))
F36: =IF(OR(D36="",E36="",E36=0),"",1000*D36/ABS(E36)) | H36: =IF(G36="","",G36/2) | I36: =IF(F36="","",DEGREES(ATAN($B$4/F36))) | J36: =IF(A36="","",IFERROR(ABS(INDEX(Steering_Target_Actual!$J$11:$J$19,MATCH(A36,Steering_Target_Actual!$B$11:$B$19,0))),"")) | K36: =IF(OR(I36="",J36=""),"",J36-I36) | L36: =IF(OR(F36="",D36=""),"",D36^2/(F36/1000))
F37: =IF(OR(D37="",E37="",E37=0),"",1000*D37/ABS(E37)) | H37: =IF(G37="","",G37/2) | I37: =IF(F37="","",DEGREES(ATAN($B$4/F37))) | J37: =IF(A37="","",IFERROR(ABS(INDEX(Steering_Target_Actual!$J$11:$J$19,MATCH(A37,Steering_Target_Actual!$B$11:$B$19,0))),"")) | K37: =IF(OR(I37="",J37=""),"",J37-I37) | L37: =IF(OR(F37="",D37=""),"",D37^2/(F37/1000))
A39: Understeer gradient K (slope of understeer over a_y, all rows) [°/(m/s²)] | I39: =IFERROR(SLOPE(K8:K37,L8:L37),"") -> 6.7454021
A40: Smallest measured radius [mm] (= turning circle/2 at full lock) | I40: =IF(COUNT(F8:F37)=0,"",MIN(F8:F37)) -> 214.13276
A41: Theoretical comparison (Ackermann_CAD) [mm] | I41: =Ackermann_CAD!B46 -> 93.386674

Sheet Drivetrain
A1: Drivetrain: speed, traction, encoder, braking (R04, R06, R11, R12)
A2: Replaces the old performance index P with physically comparable quantities.
A4: Nominal wheel diameter d [mm] | B4: 32 | C4: Fusion / mould
A5: Bevel gear ratio i (motor:axle) | B5: 1 | C5: 1:1
A6: No-load speed n₀ @ 12 V [1/min] | B6: 1000 | C6: shop data
A7: Rated motor voltage [V] | B7: 12
A8: Nominal battery voltage [V] | B8: 14.8 | C8: 4S
A9: Full battery voltage [V] | B9: 16.8 | C9: 4S
A10: Max. PWM duty cycle in the software [%] | B10: 100 | C10: full PWM 0–1023 (journal 3.1.7)
A11: Mass ready to drive [g] | B11: =IF(Mass_CoG!B55<>"",Mass_CoG!B55,Mass_CoG!C47) -> 575.3 | C11: from Mass_CoG (scale, otherwise CAD sum)
A12: x_CoG ahead of rear axle [mm] | B12: =IF(Mass_CoG!B63<>"",Mass_CoG!B63,Mass_CoG!C48) -> 59.519207 | C12: from Mass_CoG
A13: z_CoG above ground [mm] | B13: =IF(Mass_CoG!B66<>"",Mass_CoG!B66,Mass_CoG!C50) -> 31.288663 | C13: from Mass_CoG
A14: Wheelbase L [mm] | B14: =Mass_CoG!B8 -> 102
A15: Friction coefficient μ longitudinal | B15: =Grip_Tipping!C12 -> 0.87790318 | C15: from Grip_Tipping
A16: Stall torque M_stall @ 12 V [Nm] (T10) | C16: not measured: tyres slip before stalling (journal 3.1.7.2)
A17: Stall current @ 12 V [A] (T10) | C17: Traction limit: approx. 0.53 A winding current (journal)
A19: Calculated
A20: v₀ theoretical @ 12 V [m/s] | B20: =B6/B5*PI()*B4/1000/60 -> 1.6755161
A21: v₀ theoretical @ 14.8 V [m/s] (n ~ U) | B21: =B6*B8/B7/B5*PI()*B4/1000/60 -> 2.0664698
A22: v₀ theoretical @ 16.8 V [m/s] | B22: =B6*B9/B7/B5*PI()*B4/1000/60 -> 2.3457225
A23: v₀ at max. PWM and 14.8 V [m/s] | B23: =IF(B10="","",B21*B10/100) -> 2.0664698
A24: Previous documentation for comparison: v_max [m/s] | B24: 1.31
A25: Wheel force from stall torque [N] | B25: =IF(B16="","",B16*B5/(B4/2000))
A26: a_motor = F/m [m/s²] (motor launch limit) | B26: =IF(OR(B25="",B11=""),"",B25/(B11/1000))
A27: Static rear axle load [%] | B27: =IF(OR(B12="",B14=""),"",1-B12/B14) -> 0.41647836
A28: a_grip rear-wheel drive with load transfer [m/s²] | B28: =IF(OR(B15="",B12="",B13=""),"",B15*9.81*(1-B12/B14)/(1-B15*B13/B14)) -> 4.9087159
A29: Limiting factor at launch | B29: =IF(OR(B26="",B28=""),"",IF(B26<B28,"Motor","grip (wheels spin)"))
A30: Time 0 → 1 m/s at limit acceleration [s] | B30: =IF(OR(B26="",B28=""),"",1/MIN(B26,B28))
A32: Encoder calibration (T04)
A33: Run | B33: Real distance [mm] | C33: Encoder counts | D33: mm per count | E33: eff. wheel diameter [mm]
E34: (needs counts per wheel revolution, cell B45)
A35: 1 | B35: 2000 | C35: 8680 | D35: =IF(OR(B35="",C35="",C35=0),"",B35/C35) -> 0.23041475 | E35: =IF(OR(D35="",$B$45=""),"",D35*$B$45/PI()) -> 29.924063
A36: 2 | B36: 2004 | C36: 8672 | D36: =IF(OR(B36="",C36="",C36=0),"",B36/C36) -> 0.23108856 | E36: =IF(OR(D36="",$B$45=""),"",D36*$B$45/PI()) -> 30.011572
A37: 3 | B37: 2001 | C37: 8633 | D37: =IF(OR(B37="",C37="",C37=0),"",B37/C37) -> 0.23178501 | E37: =IF(OR(D37="",$B$45=""),"",D37*$B$45/PI()) -> 30.10202
A38: 4 | B38: 2002 | C38: 8675 | D38: =IF(OR(B38="",C38="",C38=0),"",B38/C38) -> 0.2307781 | E38: =IF(OR(D38="",$B$45=""),"",D38*$B$45/PI()) -> 29.971252
A39: 5 | B39: 2004 | C39: 8697 | D39: =IF(OR(B39="",C39="",C39=0),"",B39/C39) -> 0.23042428 | E39: =IF(OR(D39="",$B$45=""),"",D39*$B$45/PI()) -> 29.925302
A40: 6 | B40: 1998 | C40: 8643 | D40: =IF(OR(B40="",C40="",C40=0),"",B40/C40) -> 0.23116973 | E40: =IF(OR(D40="",$B$45=""),"",D40*$B$45/PI()) -> 30.022113
A41: 7 | B41: 2001 | C41: 8631 | D41: =IF(OR(B41="",C41="",C41=0),"",B41/C41) -> 0.23183872 | E41: =IF(OR(D41="",$B$45=""),"",D41*$B$45/PI()) -> 30.108995
A42: 8 | B42: 2000 | C42: 8634 | D42: =IF(OR(B42="",C42="",C42=0),"",B42/C42) -> 0.23164234 | E42: =IF(OR(D42="",$B$45=""),"",D42*$B$45/PI()) -> 30.083492
A43: 9 | B43: 1997 | C43: 8614 | D43: =IF(OR(B43="",C43="",C43=0),"",B43/C43) -> 0.2318319 | E43: =IF(OR(D43="",$B$45=""),"",D43*$B$45/PI()) -> 30.10811
...

Sheet Grip_Tipping
A1: Friction coefficient, cornering limit, tipping limit, slip of the rigid rear axle (T08, T12, R07–R09)
A4: Test | B4: Condition | C4: Sliding angle α [°] (5 measurements →) | H4: Mean α [°] | I4: μ = tan α
A5: Longitudinal (wheels blocked) | B5: clean | C5: 40.9 | D5: 41.2 | E5: 42.4 | F5: 40.5 | G5: 41.4 | H5: =IF(COUNT(C5:G5)=0,"",AVERAGE(C5:G5)) -> 41.28 | I5: =IF(H5="","",TAN(RADIANS(H5))) -> 0.87790318
A6: Longitudinal (wheels blocked) | B6: after 3 runs | C6: 34.1 | D6: 35.2 | E6: 35 | F6: 35.1 | G6: 33.3 | H6: =IF(COUNT(C6:G6)=0,"",AVERAGE(C6:G6)) -> 34.54 | I6: =IF(H6="","",TAN(RADIANS(H6))) -> 0.68830935
A7: Lateral | B7: clean | C7: 44.3 | D7: 44.2 | E7: 45.3 | F7: 45.4 | G7: 43.8 | H7: =IF(COUNT(C7:G7)=0,"",AVERAGE(C7:G7)) -> 44.6 | I7: =IF(H7="","",TAN(RADIANS(H7))) -> 0.98613394
A8: Lateral | B8: after 3 runs | C8: 35.6 | D8: 35.7 | E8: 35.8 | F8: 36.5 | G8: 36.7 | H8: =IF(COUNT(C8:G8)=0,"",AVERAGE(C8:G8)) -> 36.06 | I8: =IF(H8="","",TAN(RADIANS(H8))) -> 0.72814372
A9: Lateral, LEGO Spike tyre (comparison) | B9: clean | C9: 30.4 | D9: 29.8 | E9: 30.8 | F9: 30.7 | G9: 31.2 | H9: =IF(COUNT(C9:G9)=0,"",AVERAGE(C9:G9)) -> 30.58 | I9: =IF(H9="","",TAN(RADIANS(H9))) -> 0.5909273
A11: Values used
A12: μ longitudinal (clean) | C12: =I5 -> 0.87790318
A13: μ lateral (clean) | C13: =I7 -> 0.98613394
A14: z_CoG [mm] | C14: =Drivetrain!B13 -> 31.288663
A15: Track width T [mm] | C15: =Mass_CoG!B9 -> 96.2
A17: Tipping limit a_tip = g·(T/2)/h [m/s²] | C17: =IF(OR(C14="",C14=0),"",9.81*C15/2/C14) -> 15.080894
A18: Sliding limit a_slide = μ_lat·g [m/s²] | C18: =IF(C13="","",C13*9.81) -> 9.673974
A19: What happens first? | C19: =IF(OR(C17="",C18=""),"",IF(C18<C17,"slides before tipping (safe)","TIPS before sliding")) -> slides before tipping (safe)
A20: Safety factor against tipping a_tip/a_slide | C20: =IF(OR(C17="",C18="",C18=0),"",C17/C18) -> 1.558914
A22: Turning radius R (rear-axle centre) [mm] | C22: v_max = √(μ·g·R) [m/s] | D22: Slip per rear wheel ± T/(2R) | E22: Required speed inner/outer
A23: 100 | C23: =IF(C13="","",SQRT(C13*9.81*A23/1000)) -> 0.98356362 | D23: =$C$15/(2*A23) -> 0.481 | E23: =TEXT(1-$C$15/(2*A23),"0.00")&" / "&TEXT(1+$C$15/(2*A23),"0.00") -> 0.52 / 1.48
A24: 150 | C24: =IF(C13="","",SQRT(C13*9.81*A24/1000)) -> 1.2046145 | D24: =$C$15/(2*A24) -> 0.32066667 | E24: =TEXT(1-$C$15/(2*A24),"0.00")&" / "&TEXT(1+$C$15/(2*A24),"0.00") -> 0.68 / 1.32
A25: 200 | C25: =IF(C13="","",SQRT(C13*9.81*A25/1000)) -> 1.390969 | D25: =$C$15/(2*A25) -> 0.2405 | E25: =TEXT(1-$C$15/(2*A25),"0.00")&" / "&TEXT(1+$C$15/(2*A25),"0.00") -> 0.76 / 1.24
A26: 300 | C26: =IF(C13="","",SQRT(C13*9.81*A26/1000)) -> 1.7035822 | D26: =$C$15/(2*A26) -> 0.16033333 | E26: =TEXT(1-$C$15/(2*A26),"0.00")&" / "&TEXT(1+$C$15/(2*A26),"0.00") -> 0.84 / 1.16
A27: 500 | C27: =IF(C13="","",SQRT(C13*9.81*A27/1000)) -> 2.1993151 | D27: =$C$15/(2*A27) -> 0.0962 | E27: =TEXT(1-$C$15/(2*A27),"0.00")&" / "&TEXT(1+$C$15/(2*A27),"0.00") -> 0.90 / 1.10
A28: 750 | C28: =IF(C13="","",SQRT(C13*9.81*A28/1000)) -> 2.6935999 | D28: =$C$15/(2*A28) -> 0.064133333 | E28: =TEXT(1-$C$15/(2*A28),"0.00")&" / "&TEXT(1+$C$15/(2*A28),"0.00") -> 0.94 / 1.06
A29: 1000 | C29: =IF(C13="","",SQRT(C13*9.81*A29/1000)) -> 3.1103013 | D29: =$C$15/(2*A29) -> 0.0481 | E29: =TEXT(1-$C$15/(2*A29),"0.00")&" / "&TEXT(1+$C$15/(2*A29),"0.00") -> 0.95 / 1.05
